2018-03-20 02:41:26 WARNING (Recorder) [homeassistant.components.recorder] Ended unfinished session (id=59 from 2018-03-20 02:38:53.617652)
2018-03-20 02:41:33 ERROR (MainThread) [homeassistant.core] Error doing job: Task exception was never retrieved
Traceback (most recent call last):
  File "/usr/lib/python3.5/asyncio/tasks.py", line 241, in _step
    result = coro.throw(exc)
  File "/srv/homeassistant/lib/python3.5/site-packages/homeassistant/setup.py", line 60, in async_setup_component
    return (yield from task)
  File "/usr/lib/python3.5/asyncio/futures.py", line 380, in __iter__
    yield self  # This tells Task to wait for completion.
  File "/usr/lib/python3.5/asyncio/tasks.py", line 304, in _wakeup
    future.result()
  File "/usr/lib/python3.5/asyncio/futures.py", line 293, in result
    raise self._exception
  File "/usr/lib/python3.5/asyncio/tasks.py", line 239, in _step
    result = coro.send(None)
  File "/srv/homeassistant/lib/python3.5/site-packages/homeassistant/setup.py", line 159, in _async_setup_component
    conf_util.async_process_component_config(hass, config, domain)
  File "/srv/homeassistant/lib/python3.5/site-packages/homeassistant/config.py", line 622, in async_process_component_config
    platform = get_platform(domain, p_name)
  File "/srv/homeassistant/lib/python3.5/site-packages/homeassistant/loader.py", line 104, in get_platform
    return get_component(PLATFORM_FORMAT.format(domain, platform))
  File "/srv/homeassistant/lib/python3.5/site-packages/homeassistant/loader.py", line 142, in get_component
    module = importlib.import_module(path)
  File "/usr/lib/python3.5/importlib/__init__.py", line 126, in import_module
    return _bootstrap._gcd_import(name[level:], package, level)
  File "<frozen importlib._bootstrap>", line 986, in _gcd_import
  File "<frozen importlib._bootstrap>", line 969, in _find_and_load
  File "<frozen importlib._bootstrap>", line 958, in _find_and_load_unlocked
  File "<frozen importlib._bootstrap>", line 673, in _load_unlocked
  File "<frozen importlib._bootstrap_external>", line 673, in exec_module
  File "<frozen importlib._bootstrap>", line 222, in _call_with_frames_removed
  File "/home/homeassistant/.homeassistant/custom_components/climate/heatpump_thermostat.py", line 378, in <module>
    assert False
AssertionError
2018-03-20 02:41:38 WARNING (MainThread) [homeassistant.core] Unable to find service climate/set_operation_mode
2018-03-20 02:41:43 WARNING (Thread-16) [netdisco.ssdp] Error fetching description at http://192.168.1.1:1990/WFADevice.xml
2018-03-20 02:41:48 ERROR (MainThread) [homeassistant.components.media_player] Error while setting up platform plex
Traceback (most recent call last):
  File "/srv/homeassistant/lib/python3.5/site-packages/urllib3/connection.py", line 141, in _new_conn
    (self.host, self.port), self.timeout, **extra_kw)
  File "/srv/homeassistant/lib/python3.5/site-packages/urllib3/util/connection.py", line 83, in create_connection
    raise err
  File "/srv/homeassistant/lib/python3.5/site-packages/urllib3/util/connection.py", line 73, in create_connection
    sock.connect(sa)
ConnectionRefusedError: [Errno 111] Connection refused

During handling of the above exception, another exception occurred:

Traceback (most recent call last):
  File "/srv/homeassistant/lib/python3.5/site-packages/urllib3/connectionpool.py", line 601, in urlopen
    chunked=chunked)
  File "/srv/homeassistant/lib/python3.5/site-packages/urllib3/connectionpool.py", line 357, in _make_request
    conn.request(method, url, **httplib_request_kw)
  File "/usr/lib/python3.5/http/client.py", line 1107, in request
    self._send_request(method, url, body, headers)
  File "/usr/lib/python3.5/http/client.py", line 1152, in _send_request
    self.endheaders(body)
  File "/usr/lib/python3.5/http/client.py", line 1103, in endheaders
    self._send_output(message_body)
  File "/usr/lib/python3.5/http/client.py", line 934, in _send_output
    self.send(msg)
  File "/usr/lib/python3.5/http/client.py", line 877, in send
    self.connect()
  File "/srv/homeassistant/lib/python3.5/site-packages/urllib3/connection.py", line 166, in connect
    conn = self._new_conn()
  File "/srv/homeassistant/lib/python3.5/site-packages/urllib3/connection.py", line 150, in _new_conn
    self, "Failed to establish a new connection: %s" % e)
urllib3.exceptions.NewConnectionError: <urllib3.connection.HTTPConnection object at 0x66292d50>: Failed to establish a new connection: [Errno 111] Connection refused

During handling of the above exception, another exception occurred:

Traceback (most recent call last):
  File "/srv/homeassistant/lib/python3.5/site-packages/requests/adapters.py", line 440, in send
    timeout=timeout
  File "/srv/homeassistant/lib/python3.5/site-packages/urllib3/connectionpool.py", line 639, in urlopen
    _stacktrace=sys.exc_info()[2])
  File "/srv/homeassistant/lib/python3.5/site-packages/urllib3/util/retry.py", line 388, in increment
    raise MaxRetryError(_pool, url, error or ResponseError(cause))
urllib3.exceptions.MaxRetryError: HTTPConnectionPool(host='192.168.1.108', port=32400): Max retries exceeded with url: / (Caused by NewConnectionError('<urllib3.connection.HTTPConnection object at 0x66292d50>: Failed to establish a new connection: [Errno 111] Connection refused',))

During handling of the above exception, another exception occurred:

Traceback (most recent call last):
  File "/srv/homeassistant/lib/python3.5/site-packages/homeassistant/helpers/entity_component.py", line 171, in _async_setup_platform
    SLOW_SETUP_MAX_WAIT, loop=self.hass.loop)
  File "/usr/lib/python3.5/asyncio/tasks.py", line 400, in wait_for
    return fut.result()
  File "/usr/lib/python3.5/asyncio/futures.py", line 293, in result
    raise self._exception
  File "/usr/lib/python3.5/concurrent/futures/thread.py", line 55, in run
    result = self.fn(*self.args, **self.kwargs)
  File "/srv/homeassistant/lib/python3.5/site-packages/homeassistant/components/media_player/plex.py", line 87, in setup_platform
    hass, config, add_devices_callback
  File "/srv/homeassistant/lib/python3.5/site-packages/homeassistant/components/media_player/plex.py", line 106, in setup_plexserver
    token, cert_session
  File "/srv/homeassistant/lib/python3.5/site-packages/plexapi/server.py", line 103, in __init__
    data = self.query(self.key, timeout=timeout)
  File "/srv/homeassistant/lib/python3.5/site-packages/plexapi/server.py", line 341, in query
    response = method(url, headers=headers, timeout=timeout, **kwargs)
  File "/srv/homeassistant/lib/python3.5/site-packages/requests/sessions.py", line 521, in get
    return self.request('GET', url, **kwargs)
  File "/srv/homeassistant/lib/python3.5/site-packages/requests/sessions.py", line 508, in request
    resp = self.send(prep, **send_kwargs)
  File "/srv/homeassistant/lib/python3.5/site-packages/requests/sessions.py", line 618, in send
    r = adapter.send(request, **kwargs)
  File "/srv/homeassistant/lib/python3.5/site-packages/requests/adapters.py", line 508, in send
    raise ConnectionError(e, request=request)
requests.exceptions.ConnectionError: HTTPConnectionPool(host='192.168.1.108', port=32400): Max retries exceeded with url: / (Caused by NewConnectionError('<urllib3.connection.HTTPConnection object at 0x66292d50>: Failed to establish a new connection: [Errno 111] Connection refused',))
2018-03-20 02:41:58 WARNING (MainThread) [homeassistant.components.media_player] Setup of platform cast is taking over 10 seconds.
2018-03-20 02:41:59 WARNING (MainThread) [homeassistant.components.media_player] Setup of platform cast is taking over 10 seconds.
2018-03-20 02:41:59 WARNING (MainThread) [homeassistant.components.media_player] Setup of platform cast is taking over 10 seconds.
2018-03-20 02:41:59 WARNING (MainThread) [homeassistant.components.media_player] Setup of platform cast is taking over 10 seconds.
2018-03-20 02:41:59 WARNING (MainThread) [homeassistant.components.media_player] Setup of platform cast is taking over 10 seconds.
2018-03-20 02:42:00 WARNING (MainThread) [homeassistant.components.media_player] Setup of platform cast is taking over 10 seconds.
2018-03-20 02:42:18 WARNING (MainThread) [homeassistant.core] Unable to find service climate/set_operation_mode
2018-03-20 02:42:58 WARNING (MainThread) [homeassistant.core] Unable to find service climate/set_operation_mode
2018-03-20 02:43:38 WARNING (MainThread) [homeassistant.core] Unable to find service climate/set_operation_mode
2018-03-20 02:44:18 WARNING (MainThread) [homeassistant.core] Unable to find service climate/set_operation_mode
